Workbook
Name a: #REF!
Name JR_PAGE_ANCHOR_0_1: #REF!
Name JR_PAGE_ANCHOR_0_1: #REF!

Sheet Usulan pencairan
B1: Riswan Kepala Sekolah SRMA 22 Malang NIP. 197611012005021001
B2: Nomor Lampiran : | C2: : | D2: /9/KU.04.01/5/2026
B3: Lampiran | C3: : | D3: 2 berkas
B4: Hal | C4: : | D4: : Usulan Dana Kegiatan kepulangan Siswa, Kegiatan Krida, Belanja Operasional Perkantoran SRT 3 Pasuruan PPK 3
B6: Kepada Yth. PPK Wilayah 3 Pusat Pendidikan Pelatihan dan Pengembangan Profesi Di Jakarta
B8: Bersama ini kami mengajukan Dana Kegiatan Ekstrakulikuler, Belanja Operasional Perkantoran SRT 3 Pasuruan PPK 3 Bulan Juni 2026, sesuai POK Pusat Pendidikan Pelatihan dan Pengembangan Profesi TA 2026. Dengan detail kode Bagan Akun (CoA) sebagai berikut :
B10: 1. DETAIL BAGAN AKUN (CoA) URAIAN DETAIL BELANJA
B12: No. | D12: Kode Detail Bagan Akun (CoA) | E12: Uraian Detail Belanja | F12: Jumlah
B13: 1 | D13: 7936.SBE.101.303.A.521211 | E13: =RAB!C17 -> ATK Kelas | F13: =RAB!G17 -> 500000
B14: 2 | D14: 7936.SBE.101.303.A.522151 | E14: =RAB!C20 -> Honor Instruktur Ekstrakulikuler Juni-Juli [8 OK x 1LOK] | F14: =RAB!G20 -> 4000000
B15: 3 | D15: 7936.SBE.101.303.C.522141 | E15: =RAB!C24 -> Sewa Bus (2 Unit x 1KEG) | F15: =RAB!G24 -> 6600000
B16: 4 | D16: 7936.SBE.101.303.D.521219 | E16: =RAB!C28 -> Biaya Keikutsertaan Club Futsal | F16: =RAB!G28 -> 1000000
B17: 5 | D17: 7936.SBE.101.303.E.524111 | E17: =RAB!C32 -> Uang Harian Petugas Survei [2 OK x 1 HR] | F17: =RAB!G32 -> 820000
B18: 6 | D18: 7936.SBE.101.303.F.521112 | E18: =RAB!C36 -> Belanja Air Minum [410 BH x 1 PKT x 1 LOK] | F18: =RAB!G36 -> 8610000
B19: 7 | D19: 7936.SBE.101.303.M.524113 | E19: =RAB!C40 -> Transport Petugas Pendamping Lomba Atletik[1 OK x 1 Lok] | F19: =RAB!G40 -> 150000
E20: =RAB!C41 -> Transport Petugas Pendamping Lomba Pencak silat[1 OK x 1 Lok] | F20: =RAB!G41 -> 150000
E21: =RAB!C42 -> Transport Petugas Technical meeting O2SN [1 OK x 1 Lok] | F21: =RAB!G42 -> 300000
B22: 8 | D22: 7936.SBE.101.303.M.524111 | E22: =RAB!C45 -> Transport Pemulangan Libur Jeda Semester [75 OK x 1KEG] | F22: =RAB!G45 -> 11250000
E23: =RAB!C46 -> Uang Harian Petugas (8 OK x 1KEG] | F23: =RAB!G46 -> 3280000
B24: 9 | D24: 7936.SBB.101.303.A.521211 | E24: =RAB!C53 -> ATK Kelas | F24: =RAB!G53 -> 500000
B25: 10 | D25: 7936.SBB.101.303.A.522151 | E25: =RAB!C56 -> Honor Instruktur Ekstrakulikuler Juni-Juli [8 OK x 1 LOK] | F25: =RAB!G56 -> 4000000
B26: 11 | D26: 7936.SBB.101.303.C.522141 | E26: =RAB!C60 -> Sewa Bus (2 Unit x 1KEG) | F26: =RAB!G60 -> 6600000
B27: 12 | D27: 7936.SBB.101.303.D.522151 | E27: =RAB!C64 -> Biaya Keikutsertaan Club Futsal | F27: =RAB!G64 -> 1000000
B28: 13 | D28: 7936.SBB.101.303.F.521112 | E28: =RAB!C68 -> Belanja Air Minum [750 BH x 1 PKT x 1 LOK] | F28: =RAB!G68 -> 15750000
B29: 14 | D29: 7936.SBB.101.303.G.521811 | E29: =RAB!C72 -> Pembelian Obat Ringan | F29: =RAB!G72 -> 300000
B30: 15 | D30: 7936.SBB.101.303.M.524111 | E30: =RAB!C76 -> Transport Pemulangan Libur Jeda Semester dan Hari Besar Keagamaan [73 OK x 1KEG] | F30: =RAB!G76 -> 10950000
E31: =RAB!C77 -> Uang Harian Petugas (8 OK x 1KEG] | F31: =RAB!G77 -> 3280000
B32: 16 | D32: 7937.EBA.994.002.F.521111 | E32: =RAB!C84 -> Keperluan Sehari-hari Perkantoran | F32: =RAB!G84 -> 1000000
E33: =RAB!C85 -> BBM | F33: =RAB!G85 -> 1000000
B34: 18 | D34: 7937.EBA.994.002.F.522111 | E34: =RAB!C87 -> Pembayaran Listrik | F34: =RAB!G87 -> 30000000
D35: Grand Total | F35: =SUM(F13:F34) -> 111040000
B37: 2. DETAIL BAGAN AKUN (CoA) URAIAN DETAIL AKUN
B38: No. | D38: Kode Detail Bagan Akun (CoA) | E38: Uraian Akun Belanja | F38: Jumlah
B39: 1 | D39: 7936.SBE.101.303.A.521211 | E39: =RAB!C16 -> Belanja Bahan | F39: =RAB!G16 -> 500000
B40: 2 | D40: 7936.SBE.101.303.A.522151 | E40: =RAB!C19 -> Belanja Jasa Profesi | F40: =RAB!G19 -> 4000000
B41: 3 | D41: 7936.SBE.101.303.C.522141 | E41: =RAB!C23 -> Belanja Sewa | F41: =RAB!G23 -> 6600000
B42: 4 | D42: 7936.SBE.101.303.D.521219 | E42: =RAB!C27 -> Belanja Barang Non Operasional Lainnya | F42: =RAB!G27 -> 1000000
B43: 5 | D43: 7936.SBE.101.303.E.524111 | E43: =RAB!C31 -> Belanja Perjalanan Dinas Biasa | F43: =RAB!G31 -> 820000
B44: 6 | D44: 7936.SBE.101.303.F.521112 | E44: =RAB!C35 -> Belanja Pengadaan Bahan Makan | F44: =RAB!G35 -> 8610000
B45: 7 | D45: 7936.SBE.101.303.M.524113 | E45: =RAB!C39 -> Belanja Perjalanan Dinas Dalam Kota | F45: =RAB!G39 -> 600000
...

Sheet RAB
B2: RAB (RINCIAN ANGGARAN BIAYA)
B3: SEKOLAH RAKYAT 1 A PADA PPK 3 PUSAT PENDIDIKAN, PELATIHAN, DAN PENGEMBANGAN PROFESI
B4: TAHUN ANGGARAN 2026
B5: Nama Sekolah | C5: : SRT 3 Pasuruan
B6: Lokasi | C6: : Jl. Hayam Wuruk No.14 Kecamatan Purworejo Pasuruan
B7: Jenjang | C7: : SMP dan SMA
B8: Nama Kegiatan | C8: : Usulan Dana Kegiatan kepulangan Siswa, Kegiatan Krida, Belanja Operasional Perkantoran SRT 3 Pasuruan PPK 3
B10: Kode Program/Kegiatan/Komponen/Sub Komponen/Akun | C10: Jenis Belanja/Uraian | D10: Kuantitas | E10: Sat | F10: H Satuan | G10: Jumlah
B11: 01 | C11: 02 | D11: 03 | E11: 04 | F11: 05 | G11: 06
B12: SBE
B13: 7936.101
B14: 303 | C14: Kegiatan Belajar Mengajar
B15: A | C15: Sekolah Rakyat Terintegrasi 3 Pasuruan | G15: =SUM(G16,G19) -> 4500000
B16: 521211 | C16: Belanja Bahan | G16: =SUM(G17:G17) -> 500000
C17: ATK Kelas | D17: 1 | E17: PKT | F17: 500000 | G17: =SUM(D17*F17) -> 500000
B19: 522151 | C19: Belanja Jasa Profesi | G19: =SUM(G20) -> 4000000
C20: Honor Instruktur Ekstrakulikuler Juni-Juli [8 OK x 1LOK] | D20: 8 | E20: OK | F20: 500000 | G20: =SUM(D20*F20) -> 4000000
B22: C | C22: Kegiatan Krida | G22: =G24 -> 6600000
B23: 522141 | C23: Belanja Sewa | G23: =G24 -> 6600000
C24: Sewa Bus (2 Unit x 1KEG) | D24: 2 | E24: UNIT | F24: 3300000 | G24: =SUM(D24*F24) -> 6600000
B26: D | C26: Karya Ilmiah dan Latihan Olah Bakat dan Minat | G26: =G27 -> 1000000
B27: 521219 | C27: Belanja Barang Non Operasional Lainnya | G27: =SUM(G28:G28) -> 1000000
C28: Biaya Keikutsertaan Club Futsal | D28: 2 | E28: KEG | F28: 500000 | G28: =SUM(D28*F28) -> 1000000
B30: E | C30: Koordinasi dan Konsultasi Sekolah Rakyat | G30: =G32 -> 820000
B31: 524111 | C31: Belanja Perjalanan Dinas Biasa | G31: =G32 -> 820000
C32: Uang Harian Petugas Survei [2 OK x 1 HR] | D32: 2 | E32: OK | F32: 410000 | G32: =SUM(D32*F32) -> 820000
B34: F | C34: Permakanan dan Perawatan Siswa | G34: =G36 -> 8610000
B35: 521112 | C35: Belanja Pengadaan Bahan Makan | G35: =SUM(G36) -> 8610000
C36: Belanja Air Minum [410 BH x 1 PKT x 1 LOK] | D36: 410 | E36: BH | F36: 21000 | G36: =D36*F36 -> 8610000
B38: M | C38: Dukungan Penyelenggaraan Operasional Sekolah Rakyat | G38: =SUM(G39,G44) -> 15130000
B39: 524113 | C39: Belanja Perjalanan Dinas Dalam Kota | G39: =SUM(G40:G42) -> 600000
C40: Transport Petugas Pendamping Lomba Atletik[1 OK x 1 Lok] | D40: 1 | E40: OK | F40: 150000 | G40: =SUM(D40*F40) -> 150000
C41: Transport Petugas Pendamping Lomba Pencak silat[1 OK x 1 Lok] | D41: 1 | E41: OK | F41: 150000 | G41: =SUM(D41*F41) -> 150000
C42: Transport Petugas Technical meeting O2SN [1 OK x 1 Lok] | D42: 2 | E42: OK | F42: 150000 | G42: =SUM(D42*F42) -> 300000
B44: 524111 | C44: Belanja Perjalanan Dinas Biasa | G44: =SUM(G45:G46) -> 14530000
C45: Transport Pemulangan Libur Jeda Semester [75 OK x 1KEG] | D45: 75 | E45: OK | F45: 150000 | G45: =SUM(D45*F45) -> 11250000
C46: Uang Harian Petugas (8 OK x 1KEG] | D46: 8 | E46: OK | F46: 410000 | G46: =SUM(D46*F46) -> 3280000
B48: SBB
B49: 7936.101
B50: 303 | C50: Kegiatan Belajar Mengajar
...

Sheet BelanjaBahan
B2: RAB (RINCIAN ANGGARAN BIAYA)
B3: SEKOLAH RAKYAT 1 A PADA PPK 3 PUSAT PENDIDIKAN, PELATIHAN, DAN PENGEMBANGAN PROFESI
B4: TAHUN ANGGARAN 2026
B5: Nama Sekolah | C5: : SRT 3 Pasuruan
B6: Lokasi | C6: : Jl. Hayam Wuruk No.14 Kecamatan Purworejo Pasuruan
B7: Jenjang | C7: : SMP dan SMA
B8: Nama Kegiatan | C8: : Usulan Dana Kegiatan Belanja ATK Kelas SRT 3 Pasuruan PPK 3
B10: Kode Program/Kegiatan/Komponen/Sub Komponen/Akun | C10: Jenis Belanja/Uraian | D10: Kuantitas | E10: Sat | F10: H Satuan | G10: Jumlah
B11: 01 | C11: 02 | D11: 03 | E11: 04 | F11: 05 | G11: 06
B13: SBE
B14: 7936.101
B15: 303 | C15: Kegiatan Belajar Mengajar
B16: A | C16: Sekolah Rakyat Terintegrasi 3 Pasuruan | G16: =G17 -> 500000
B17: 521211 | C17: Belanja Bahan | G17: =SUM(G18:G18) -> 500000
C18: ATK Kelas | D18: 1 | E18: PKT | F18: =RAB!F17 -> 500000 | G18: =SUM(D18*F18) -> 500000
B20: SBB
B21: 7936.101
B22: 303 | C22: Kegiatan Belajar Mengajar
B23: A | C23: Sekolah Rakyat Terintegrasi 3 Pasuruan | G23: =G24 -> 500000
B24: 521211 | C24: Belanja Bahan | G24: =SUM(G25:G25) -> 500000
C25: ATK Kelas | D25: 1 | E25: PKT | F25: =RAB!F53 -> 500000 | G25: =SUM(D25*F25) -> 500000
B27: JUMLAH TOTAL RAB | G27: =G16+G23 -> 1000000 | I27: =G16+G23 -> 1000000
F30: Pasuruan, 26 Mei 2026
F31: Yang mengajukan,
F32: Kepala SRT 3 Pasuruan
F39: Julianto, S.Pd.
F40: NIP. 197304282008011006

Sheet Honor
B2: RAB (RINCIAN ANGGARAN BIAYA)
B3: SEKOLAH RAKYAT 1 A PADA PPK 3 PUSAT PENDIDIKAN, PELATIHAN, DAN PENGEMBANGAN PROFESI
B4: TAHUN ANGGARAN 2026
B5: Nama Sekolah | C5: : SRT 3 Pasuruan
B6: Lokasi | C6: : Jl. Hayam Wuruk No.14 Kecamatan Purworejo Pasuruan
B7: Jenjang | C7: : SMP dan SMA
B8: Nama Kegiatan | C8: : Usulan Dana untuk Honor Kegiatan Ekstrakulikuler SRT 3 Pasuruan PPK 3
B11: Kode Program/Kegiatan/Komponen/Sub Komponen/Akun | C11: Jenis Belanja/Uraian | D11: Kuantitas | E11: Sat | F11: H Satuan | G11: Jumlah
B12: 01 | C12: 02 | D12: 03 | E12: 04 | F12: 05 | G12: 06
B14: SBE
B15: 7936.101
B16: 303 | C16: Sekolah Rakyat Terintegrasi 3 Pasuruan
B17: A | C17: Kegiatan Belajar Mengajar | G17: =G18 -> 4000000
B18: 522151 | C18: Belanja Jasa Profesi | G18: =SUM(G19) -> 4000000
C19: Honor Instruktur Ekstrakulikuler Juni-Juli [8 ORG x 1KEG x 1LOK] | D19: 8 | E19: OK | F19: 500000 | G19: =SUM(D19*F19) -> 4000000
B21: SBB
B22: 7936.101
B23: 303 | C23: Sekolah Rakyat Terintegrasi 3 Pasuruan
B24: A | C24: Kegiatan Belajar Mengajar | G24: =G25 -> 4000000
B25: 522151 | C25: Belanja Jasa Profesi | G25: =SUM(G26) -> 4000000
C26: Honor Instruktur Ekstrakulikuler [8 ORG x 1KEG x 1LOK] | D26: 8 | E26: OK | F26: 500000 | G26: =SUM(D26*F26) -> 4000000
B28: JUMLAH TOTAL RAB | G28: =SUM(G17,G24) -> 8000000 | I28: =G19+G26 -> 8000000
F31: Pasuruan, 26 Mei 2026
F32: Yang mengajukan,
F33: Kepala SRT 3 Pasuruan
F40: Julianto, S.Pd.
F41: NIP. 197304282008011006

Sheet KegiatanKrida
B2: RAB (RINCIAN ANGGARAN BIAYA)
B3: SEKOLAH RAKYAT 1 A PADA PPK 3 PUSAT PENDIDIKAN, PELATIHAN, DAN PENGEMBANGAN PROFESI
B4: TAHUN ANGGARAN 2026
B5: Nama Sekolah | C5: : SRT 3 Pasuruan
B6: Lokasi | C6: : Jl. Hayam Wuruk No.14 Kecamatan Purworejo Pasuruan
B7: Jenjang | C7: : SMP dan SMA
B8: Nama Kegiatan | C8: : Usulan Dana Kegiatan Krida Sewa Bus SRT 3 Pasuruan PPK 3
B11: Kode Program/Kegiatan/Komponen/Sub Komponen/Akun | C11: Jenis Belanja/Uraian | D11: Kuantitas | E11: Sat | F11: H Satuan | G11: Jumlah
B12: 01 | C12: 02 | D12: 03 | E12: 04 | F12: 05 | G12: 06
B13: SBE
B14: 7936.101
B15: 303 | C15: Sekolah Rakyat Terintegrasi 3 Pasuruan
B16: C | C16: Kegiatan Krida | G16: =G18 -> 6600000
B17: 522141 | C17: Belanja Sewa | G17: =G18 -> 6600000
C18: Sewa Bus (2 Unit x 1KEG) | D18: 2 | E18: UNIT | F18: 3300000 | G18: =SUM(D18*F18) -> 6600000
B20: SBB
B21: 7936.101
B22: 303 | C22: Sekolah Rakyat Terintegrasi 3 Pasuruan
B23: C | C23: Kegiatan Krida | G23: =G24 -> 6600000
B24: 522141 | C24: Belanja Sewa | G24: =G25 -> 6600000
C25: Sewa Bus (2 Unit x 1KEG) | D25: 2 | E25: UNIT | F25: 3300000 | G25: =SUM(D25*F25) -> 6600000
B27: JUMLAH TOTAL RAB | G27: =SUM(G16,G23) -> 13200000
E30: Pasuruan, 26 Mei 2026
E31: Yang mengajukan,
E32: Kepala SRT 3 Pasuruan
E38: Julianto, S.Pd.
E39: NIP. 197304282008011006

Sheet OlahMinatBakat
B2: RAB (RINCIAN ANGGARAN BIAYA)
B3: SEKOLAH RAKYAT 1 A PADA PPK 3 PUSAT PENDIDIKAN, PELATIHAN, DAN PENGEMBANGAN PROFESI
B4: TAHUN ANGGARAN 2026
B5: Nama Sekolah | C5: : SRT 3 Pasuruan
B6: Lokasi | C6: : Jl. Hayam Wuruk No.14 Kecamatan Purworejo Pasuruan
B7: Jenjang | C7: : SMP dan SMA
B8: Nama Kegiatan | C8: : Usulan Dana Kegiatan keikutsertaan club SRT 3 Pasuruan PPK 3
B11: Kode Program/Kegiatan/Komponen/Sub Komponen/Akun | C11: Jenis Belanja/Uraian | D11: Kuantitas | E11: Sat | F11: H Satuan | G11: Jumlah
B12: 01 | C12: 02 | D12: 03 | E12: 04 | F12: 05 | G12: 06
B14: SBE
B15: 7936.101
B16: 303 | C16: Sekolah Rakyat Terintegrasi 3 Pasuruan
B17: D | C17: Karya Ilmiah dan Latihan Olah Bakat dan Minat | G17: =G18 -> 1000000
B18: 521219 | C18: Belanja Barang Non Operasional Lainnya | G18: =SUM(G19:G19) -> 1000000
C19: Biaya Keikutsertaan Club Futsal | D19: 2 | E19: KEG | F19: 500000 | G19: =D19*F19 -> 1000000
B21: SBB
B22: 7936.101
B23: 303 | C23: Sekolah Rakyat Terintegrasi 3 Pasuruan
B24: D | C24: Karya Ilmiah dan Latihan Olah Bakat dan Minat | G24: =SUM(G25) -> 1000000
B25: 521219 | C25: Belanja Barang Non Operasional Lainnya | G25: =SUM(G26:G27) -> 1000000
C26: Biaya Keikutsertaan Club Futsal | D26: 2 | E26: KEG | F26: 500000 | G26: =SUM(D26*F26) -> 1000000
B28: JUMLAH TOTAL RAB | G28: =SUM(G17,G24) -> 2000000 | I28: =G19+G26 -> 2000000
F31: Pasuruan, 26 Mei 2026
F32: Yang mengajukan,
F33: Kepala SRT 3 Pasuruan
F39: Julianto, S.Pd.
F40: NIP. 197304282008011006

Sheet Survei
B2: RAB (RINCIAN ANGGARAN BIAYA)
B3: SEKOLAH RAKYAT 1 A PADA PPK 3 PUSAT PENDIDIKAN, PELATIHAN, DAN PENGEMBANGAN PROFESI
B4: TAHUN ANGGARAN 2026
B5: Nama Sekolah | C5: : SRT 3 Pasuruan
B6: Lokasi | C6: : Jl. Hayam Wuruk No.14 Kecamatan Purworejo Pasuruan
B7: Jenjang | C7: : SMP
B8: Nama Kegiatan | C8: Uang Harian Petugas Survei
B11: Kode Program/Kegiatan/Komponen/Sub Komponen/Akun | C11: Jenis Belanja/Uraian | D11: Kuantitas | E11: Sat | F11: H Satuan | G11: Jumlah
B12: 01 | C12: 02 | D12: 03 | E12: 04 | F12: 05 | G12: 06
B13: SBE
B14: 7936.101
B15: 303
B16: E | C16: Koordinasi dan Konsultasi Sekolah Rakyat | G16: =G18 -> 820000
B17: 524111 | C17: Belanja Perjalanan Dinas Biasa | G17: =G18 -> 820000
C18: Uang Harian Petugas [2 OK x 1 HR x 1 Lok] | D18: 2 | E18: OK | F18: 410000 | G18: =SUM(D18*F18) -> 820000
B20: JUMLAH TOTAL RAB | G20: =SUM(G16) -> 820000
E23: Pasuruan, 26 Mei 2026
E24: Yang mengajukan,
E25: Kepala SRT 3 Pasuruan
E31: Julianto, S.Pd.
E32: NIP. 197304282008011006

Sheet PermakananSiswa
B3: RAB (RINCIAN ANGGARAN BIAYA)
B4: SEKOLAH RAKYAT 1 A PADA PPK 3 PUSAT PENDIDIKAN, PELATIHAN, DAN PENGEMBANGAN PROFESI
B5: TAHUN ANGGARAN 2026
B6: Nama Sekolah | C6: : SRT 3 Pasuruan
B7: Lokasi | C7: : Jl. Hayam Wuruk No.14 Kecamatan Purworejo Pasuruan
B8: Jenjang | C8: : SMP dan SMA
B9: Nama Kegiatan | C9: : Usulan Dana Kegiatan Belanja Permakanan (Belanja Air Minum) SRT 3 Pasuruan PPK 3
B12: Kode Program/Kegiatan/Komponen/Sub Komponen/Akun | C12: Jenis Belanja/Uraian | D12: Kuantitas | E12: Sat | F12: H Satuan | G12: Jumlah
B13: 01 | C13: 02 | D13: 03 | E13: 04 | F13: 05 | G13: 06
B14: SBE
B15: 7936.101
B16: 303
B17: F | C17: Permakanan dan Perawatan Siswa | G17: =SUM(G18) -> 8610000
B18: 521112 | C18: Belanja Pengadaan Bahan Makan | G18: =SUM(G19:G19) -> 8610000
C19: Belanja Air Minum [410 BH x 1 PKT x 1 LOK] | D19: 410 | E19: BH | F19: 21000 | G19: =D19*F19 -> 8610000
B21: SBB
B22: 7936.101
B23: 303
B24: F | C24: Permakanan dan Perawatan Siswa | G24: =G25 -> 15750000
B25: 521112 | C25: Belanja Pengadaan Bahan Makan | G25: =G26 -> 15750000
C26: Belanja Air Minum [750 BH x 1 PKT x 1 LOK] | D26: 750 | E26: BH | F26: 21000 | G26: =D26*F26 -> 15750000
B29: JUMLAH TOTAL RAB | G29: =SUM(G17,G24) -> 24360000 | I29: =G19+G26 -> 24360000
F32: Pasuruan, 26 Mei 2026
F33: Yang mengajukan,
F34: Kepala SRT 3 Pasuruan
F41: Julianto, S.Pd.
F42: NIP. 197304282008011006

Sheet Obat
B3: RAB (RINCIAN ANGGARAN BIAYA)
B4: SEKOLAH RAKYAT 1 A PADA PPK 3 PUSAT PENDIDIKAN, PELATIHAN, DAN PENGEMBANGAN PROFESI
B5: TAHUN ANGGARAN 2026
B6: Nama Sekolah | C6: : SRT 3 Pasuruan
B7: Lokasi | C7: : Jl. Hayam Wuruk No.14 Kecamatan Purworejo Pasuruan
B8: Jenjang | C8: : SMA
B9: Nama Kegiatan | C9: : Usulan Dana Kegiatan Belanja Persediaan (Pembelian Obat) SRT 3 Pasuruan PPK 3
B12: Kode Program/Kegiatan/Komponen/Sub Komponen/Akun | C12: Jenis Belanja/Uraian | D12: Kuantitas | E12: Sat | F12: H Satuan | G12: Jumlah
B13: 01 | C13: 02 | D13: 03 | E13: 04 | F13: 05 | G13: 06
B14: SBB
B15: 7936.101
B16: 303
B17: G | C17: Perlengkapan Operasional Sekolah | G17: =G18 -> 300000
B18: 521811 | C18: Belanja Barang Persediaan Barang Konsumsi | G18: =G19 -> 300000
C19: Pembelian Obat Ringan | D19: 1 | E19: PKT | F19: 300000 | G19: =D19*F19 -> 300000
B22: JUMLAH TOTAL RAB | G22: =SUM(G17) -> 300000 | I22: =G19 -> 300000
F25: Pasuruan, 26 Mei 2026
F26: Yang mengajukan,
F27: Kepala SRT 3 Pasuruan
F34: Julianto, S.Pd.
F35: NIP. 197304282008011006

Sheet TransportPendamping
B2: RAB (RINCIAN ANGGARAN BIAYA)
B3: SEKOLAH RAKYAT 1 A PADA PPK 3 PUSAT PENDIDIKAN, PELATIHAN, DAN PENGEMBANGAN PROFESI
B4: TAHUN ANGGARAN 2026
B5: Nama Sekolah | C5: : SRT 3 Pasuruan
B6: Lokasi | C6: : Jl. Hayam Wuruk No.14 Kecamatan Purworejo Pasuruan
B7: Jenjang | C7: : SMA
B8: Nama Kegiatan | C8: : Usulan Dana Transportasi Pendamping Kegiatan SRT 3 Pasuruan PPK 3
B11: Kode Program/Kegiatan/Komponen/Sub Komponen/Akun | C11: Jenis Belanja/Uraian | D11: Kuantitas | E11: Sat | F11: H Satuan | G11: Jumlah
B12: 01 | C12: 02 | D12: 03 | E12: 04 | F12: 05 | G12: 06
B13: SBE
B14: 7936.101
B15: 303 | C15: Sekolah Rakyat Terintegrasi 3 Pasuruan
B16: M | C16: Dukungan Penyelenggaraan Operasional Sekolah Rakyat | G16: =G17 -> 600000
B17: 524113 | C17: Belanja Perjalanan Dinas Dalam Kota | G17: =SUM(G18:G20) -> 600000
C18: Transport Petugas Pendamping Lomba Atletik[1 OK x 1 Lok] | D18: 1 | E18: OK | F18: 150000 | G18: =SUM(D18*F18) -> 150000
C19: Transport Petugas Pendamping Lomba Pencak silat[1 OK x 1 Lok] | D19: 1 | E19: OK | F19: 150000 | G19: =SUM(D19*F19) -> 150000
C20: Transport Petugas Technical meeting O2SN [1 OK x 1 Lok] | D20: 2 | E20: OK | F20: 150000 | G20: =SUM(D20*F20) -> 300000
B22: JUMLAH TOTAL RAB | G22: =SUM(G16) -> 600000 | I22: =G18+G19+G20 -> 600000
F25: Pasuruan, 26 Mei 2026
F26: Yang mengajukan,
F27: Kepala SRT 3 Pasuruan
F33: Julianto, S.Pd.
F34: NIP. 197304282008011006

Sheet PemulanganSiswa
B2: RAB (RINCIAN ANGGARAN BIAYA)
B3: SEKOLAH RAKYAT 1 A PADA PPK 3 PUSAT PENDIDIKAN, PELATIHAN, DAN PENGEMBANGAN PROFESI
B4: TAHUN ANGGARAN 2026
B5: Nama Sekolah | C5: : SRT 3 Pasuruan
B6: Lokasi | C6: : Jl. Hayam Wuruk No.14 Kecamatan Purworejo Pasuruan
B7: Jenjang | C7: : SMP dan SMA
B8: Nama Kegiatan | C8: : Usulan Dana Transport Kepulangan Siswa SRT 3 Pasuruan PPK 3
B11: Kode Program/Kegiatan/Komponen/Sub Komponen/Akun | C11: Jenis Belanja/Uraian | D11: Kuantitas | E11: Sat | F11: H Satuan | G11: Jumlah
B12: 01 | C12: 02 | D12: 03 | E12: 04 | F12: 05 | G12: 06
B13: SBE
B14: 7936.101
B15: 303 | C15: Sekolah Rakyat Terintegrasi 3 Pasuruan
B16: M | C16: Dukungan Penyelenggaraan Operasional Sekolah Rakyat | G16: =G17 -> 14530000
B17: 524111 | C17: Belanja Perjalanan Dinas Biasa | G17: =SUM(G18:G19) -> 14530000
C18: Transport Pemulangan Libur Jeda Semester dan Hari Besar Keagamaan [75 OK x 1KEG] | D18: 75 | E18: OK | F18: 150000 | G18: =SUM(D18*F18) -> 11250000
C19: Uang Harian Petugas (8 OK x 1KEG] | D19: 8 | E19: OK | F19: 410000 | G19: =SUM(D19*F19) -> 3280000
B21: SBB
B22: 7936.101
B23: 303 | C23: Sekolah Rakyat Terintegrasi 3 Pasuruan
B24: M | C24: Dukungan Penyelenggaraan Operasional Sekolah Rakyat | G24: =G25 -> 14230000
B25: 524111 | C25: Belanja Perjalanan Dinas Biasa | G25: =SUM(G26:G27) -> 14230000
C26: Transport Pemulangan Libur Jeda Semester dan Hari Besar Keagamaan [73 OK x 1KEG] | D26: 73 | E26: OK | F26: 150000 | G26: =SUM(D26*F26) -> 10950000
C27: Uang Harian Petugas (8 OK x 1KEG] | D27: 8 | E27: OK | F27: 410000 | G27: =SUM(D27*F27) -> 3280000
B29: JUMLAH TOTAL RAB | G29: =SUM(G16,G24) -> 28760000 | I29: =G18+G19+G26+G27 -> 28760000
F32: Pasuruan, 26 Mei 2026
F33: Yang mengajukan,
F34: Kepala SRT 3 Pasuruan
F40: Julianto, S.Pd.
F41: NIP. 197304282008011006

Sheet EBA
B2: RAB (RINCIAN ANGGARAN BIAYA)
B3: SEKOLAH RAKYAT 1 A PADA PPK 3 PUSAT PENDIDIKAN, PELATIHAN, DAN PENGEMBANGAN PROFESI
B4: TAHUN ANGGARAN 2026
B5: Nama Sekolah | C5: : SRT 3 Pasuruan
B6: Lokasi | C6: : Jl. Hayam Wuruk No.14 Kecamatan Purworejo Pasuruan
B7: Jenjang | C7: : SMP dan SMA
B8: Nama Kegiatan | C8: : Usulan Dana Operasional Perkantoran SRT 3 Pasuruan PPK 3
B11: Kode Program/Kegiatan/Komponen/Sub Komponen/Akun | C11: Jenis Belanja/Uraian | D11: Kuantitas | E11: Sat | F11: H Satuan | G11: Jumlah
B12: 01 | C12: 02 | D12: 03 | E12: 04 | F12: 05 | G12: 06
B14: 7937.EBA.994 | C14: Layanan Perkantoran
B15: 002 | C15: Operasional dan Pemeliharaan Perkantoran
B16: F | C16: Operasional Perkantoran | G16: =SUM(G17) -> 2000000
B17: 521111 | C17: Belanja Keperluan Perkantoran | G17: =SUM(G18:G19) -> 2000000
C18: Keperluan Sehari-hari Perkantoran | F18: 1000000 | G18: =F18 -> 1000000
C19: BBM | F19: =RAB!G85 -> 1000000 | G19: =F19 -> 1000000
B21: 522111 | C21: Pembayaran Listrik | D21: 2 | E21: PKT | F21: 15000000 | G21: =SUM(D21*F21) -> 30000000
B23: JUMLAH TOTAL RAB | G23: =SUM(G17,G21) -> 32000000 | I23: =G18+G19+G21 -> 32000000
F26: Pasuruan, 26 Mei 2026
F27: Yang mengajukan,
F28: Kepala SRT 3 Pasuruan
F35: Julianto, S.Pd.
F36: NIP. 197304282008011006

Sheet TOTAL SELURUH RAB
B3: BELANJA BAHAN | C3: =BelanjaBahan!G27 -> 1000000
B4: HONOR | C4: =Honor!G28 -> 8000000
B5: KEGIATAN KRIDA | C5: =KegiatanKrida!G27 -> 13200000
B6: OLAH MINAT BAKAT | C6: =OlahMinatBakat!G28 -> 2000000
B7: SURVEI | C7: =Survei!G20 -> 820000
B8: PERMAKANAN SISWA | C8: =PermakananSiswa!G29 -> 24360000
B9: OBAT | C9: =Obat!G22 -> 300000
B10: TRANSPORT PENDAMPING KEGIATAN | C10: =TransportPendamping!G22 -> 600000
B11: PEMULANGAN SISWA | C11: =PemulanganSiswa!G29 -> 28760000
B12: OPERASIONAL PERKANTORAN | C12: =EBA!G23 -> 32000000
C14: =SUM(C3:C12) -> 111040000

Sheet catatan
A1: KEBUTUHAN ADMINISTRASI | G1: orientasi dan praktikum komunitas
A3: 1.Surat kepala sekolah untuk permohonan narasumber (diminta cv pegawai atau non pegawai)
A4: 2.Setelah dapat balasan dari mereka, kepala sekolah membuat draf SK KPA Kegiatan tersebut
A5: 3.surat tugas kegiatan ; dari kapus
A6: 4.tanda terima makan kegiatan
A7: 5.tanda terima snack kegiatan
A8: 6.presensi kehadiran peserta kegiatan
A9: 7.dokumentasi kegiatan
