Workbook
Name JR_PAGE_ANCHOR_0_1: SMP!$A$3
Name JR_PAGE_ANCHOR_0_1: SD!$B$4

Sheet SD
B2: KODE AKUN | D2: PROGRAM/KEG/KOUTPUT/SUBOUTPUT/KOMPONEN/SUBKOMP/DETIL | G2: VOL | H2: SAT | I2: H SATUAN | J2: PAGU | K2: REALISASI | O2: SALDO
K3: SP2D | L3: % | M3: AKRURAL | N3: % | O3: SP2D | P3: AKRURAL
B4: 027.01.DQ | D4: Program Perlindungan Sosial | J4: 2097544232000
B5: 7936 | D5: Penyelenggaraan Program Sekolah Rakyat | J5: 2088632535000
B6: 7936.SBC | D6: Pendidikan Dasar[Penambahan alokasi dari SABA 999.08 ke 9A] | J6: =J8+J152+J296+J440+J584+J728+J872+J1016 -> 21502843000 | K6: =K8+K152+K296+K440+K584+K728+K872+K1016 -> 702852000 | L6: =(K6/J6)*100 -> 3.2686468 | M6: =M8+M152+M296+M440+M584+M728+M872+M1016 -> 1354727491 | N6: =(M6/J6)*100 -> 6.300225 | O6: =O8+O152+O296+O440+O584+O728+O872+O1016 -> 20799991000 | P6: =P8+P152+P296+P440+P584+P728+P872+P1016 -> 20148115509
D7: Lokasi : KOTA JAKARTA PUSAT
B8: 302 | D8: Sekolah Rakyat Terintegrasi 2 Banyuwangi | J8: =J9+J23+J35+J48+J65+J74+J84+J89+J105+J119+J127+J135+J141 -> 2060121000 | K8: =K9+K23+K35+K48+K65+K74+K84+K89+K105+K119+K127+K135+K141 -> 44809500 | M8: =M9+M23+M35+M48+M65+M74+M84+M89+M105+M119+M127+M135+M141 -> 172139900 | O8: =J8-K8 -> 2015311500 | P8: =J8-M8 -> 1887981100
B9: A | D9: Kegiatan Belajar Mengajar | J9: =J10+J19 -> 90140000 | K9: =K10+K19 -> 0 | M9: =M10+M19 -> 10371000 | O9: =J9-K9 -> 90140000 | P9: =J9-M9 -> 79769000
B10: 521211 | D10: Belanja Bahan | J10: =SUM(J12:J18) -> 82140000 | K10: =SUM(K12:K18) -> 0 | M10: =SUM(M12:M18) -> 6871000 | O10: =J10-K10 -> 82140000 | P10: =J10-M10 -> 75269000
D11: (KPPN.182-Jakarta VII ) | O11: =J11-K11 -> 0 | P11: =J11-M11 -> 0
D12: - | E12: ATK Kelas [1 PKT x 12 BLN x 1 ROM] | G12: 12 | H12: OK | I12: 500000 | J12: =G12*I12 -> 6000000 | O12: =J12-K12 -> 6000000 | P12: =J12-M12 -> 6000000
D13: - | E13: Buku Pegangan Guru [1 PKT x 2 SMT x 1 LOK] | G13: 2 | H13: OK | I13: 2000000 | J13: =G13*I13 -> 4000000 | O13: =J13-K13 -> 4000000 | P13: =J13-M13 -> 4000000
D14: - | E14: Buku Penunjang Kegiatan Belajar Mengajar [5 PKT x 2 SMT x 1 LOK] | G14: 10 | H14: OK | I14: 500000 | J14: =G14*I14 -> 5000000 | O14: =J14-K14 -> 5000000 | P14: =J14-M14 -> 5000000 | Q14: 521211 | R14: ATK Kelas [1 PKT x 12 BLN x 1 ROM] Buku Pegangan Guru [1 PKT x 2 SMT x 1 LOK] Buku Penunjang Kegiatan Belajar Mengajar [5 PKT x 2 SMT x 1 LOK] Penggandaan Soal [25 ORG x 4 KEG x 1 ROM] Konsumsi Rapat Eksternal [40 ORG x 4 KEG x 2 HR x 1 LOK Snack Rapat Eksternal [40 ORG x 4 KEG x 2 HR x 1 LOK
D15: - | E15: Penggandaan Soal [25 ORG x 4 KEG x 1 ROM] | G15: 100 | H15: OK | I15: 25000 | J15: =G15*I15 -> 2500000 | M15: 725000 | O15: =J15-K15 -> 2500000 | P15: =J15-M15 -> 1775000 | Q15: 521211
D16: - | E16: Konsumsi Rapat Eksternal [40 ORG x 4 KEG x 2 HR x 1 LOK | G16: 320 | H16: OK | I16: 53000 | J16: =G16*I16 -> 16960000 | M16: 3920000 | O16: =J16-K16 -> 16960000 | P16: =J16-M16 -> 13040000 | Q16: 521211
D17: - | E17: Snack Rapat Eksternal [40 ORG x 4 KEG x 2 HR x 1 LOK | G17: 320 | H17: OK | I17: 24000 | J17: =G17*I17 -> 7680000 | M17: 1600000 | O17: =J17-K17 -> 7680000 | P17: =J17-M17 -> 6080000 | Q17: 521211
D18: - | E18: Media Pembelajaran dan laporan perekembangan siswa [25 ORG x 2 PKT x 1 ROM] | G18: 50 | H18: OK | I18: 800000 | J18: =G18*I18 -> 40000000 | M18: 626000 | O18: =J18-K18 -> 40000000 | P18: =J18-M18 -> 39374000
B19: 522151 | D19: Belanja Jasa Profesi | J19: =SUM(J21:J22) -> 8000000 | K19: =SUM(K21:K22) -> 0 | M19: =SUM(M21:M22) -> 3500000 | O19: =J19-K19 -> 8000000 | P19: =J19-M19 -> 4500000
D20: (KPPN.182-Jakarta VII ) | O20: =J20-K20 -> 0 | P20: =J20-M20 -> 0
D21: - | E21: Honor Instruktur [4 ORG x 2 Jam x 1 ROM] | G21: 8 | H21: OK | I21: 500000 | J21: =G21*I21 -> 4000000 | M21: 3500000 | O21: =J21-K21 -> 4000000 | P21: =J21-M21 -> 500000
D22: - | E22: Honor Narasumber [4 ORG x 2 Jam] | G22: 8 | H22: OK | I22: 500000 | J22: =G22*I22 -> 4000000 | O22: =J22-K22 -> 4000000 | P22: =J22-M22 -> 4000000
B23: B | D23: Praktikum Komunitas | J23: =J24+J29+J32 -> 13750000 | K23: =K24+K29+K32 -> 0 | M23: =M24+M29+M32 -> 0 | O23: =J23-K23 -> 13750000 | P23: =J23-M23 -> 13750000 | Q23: isi yang bener
B24: 521211 | D24: Belanja Bahan | J24: =SUM(J26:J28) -> 3750000 | K24: =SUM(K26:K28) -> 0 | M24: =SUM(M26:M28) -> 0 | O24: =J24-K24 -> 3750000 | P24: =J24-M24 -> 3750000
D25: (KPPN.182-Jakarta VII ) | O25: =J25-K25 -> 0 | P25: =J25-M25 -> 0
D26: - | E26: Snack dan Konsumsi Peserta [25 ORG x 2 keg x 1 Rom] | G26: 50 | H26: OK | I26: 53000 | J26: =G26*I26 -> 2650000 | O26: =J26-K26 -> 2650000 | P26: =J26-M26 -> 2650000
D27: - | E27: Dokumentasi Pelaporan [1 KEG x 2 LOK] | G27: 2 | H27: OK | I27: 250000 | J27: =G27*I27 -> 500000 | O27: =J27-K27 -> 500000 | P27: =J27-M27 -> 500000
D28: - | E28: Spanduk [1 KEG x 2 LOK] | G28: 2 | H28: OK | I28: 300000 | J28: =G28*I28 -> 600000 | O28: =J28-K28 -> 600000 | P28: =J28-M28 -> 600000
B29: 521213 | D29: Belanja Honor Output Kegiatan | J29: =J31 -> 2000000 | O29: =J29-K29 -> 2000000 | P29: =J29-M29 -> 2000000
D30: (KPPN.182-Jakarta VII ) | O30: =J30-K30 -> 0 | P30: =J30-M30 -> 0
D31: - | E31: Honor Pemandu Praktikum [2 ORG x 2 KEG x 1 ROM] | G31: 4 | H31: OK | I31: 500000 | J31: =G31*I31 -> 2000000 | O31: =J31-K31 -> 2000000 | P31: =J31-M31 -> 2000000
B32: 522141 | D32: Belanja Sewa | J32: =J34 -> 8000000 | K32: =K34 | M32: =M34 | O32: =J32-K32 -> 8000000 | P32: =J32-M32 -> 8000000
D33: (KPPN.182-Jakarta VII ) | O33: =J33-K33 -> 0 | P33: =J33-M33 -> 0
D34: - | E34: Sewa Bus [1 UNIT x 2 keg x 1 ROm] | G34: 2 | H34: OK | I34: 4000000 | J34: =G34*I34 -> 8000000 | O34: =J34-K34 -> 8000000 | P34: =J34-M34 -> 8000000
B35: C | D35: Kegiatan Krida | J35: =J36+J42+J45 -> 30400000 | K35: =K36+K42+K45 -> 0 | M35: =M36+M42+M45 -> 0 | O35: =J35-K35 -> 30400000 | P35: =J35-M35 -> 30400000
B36: 521211 | D36: Belanja Bahan | J36: =SUM(J38:J41) -> 20400000 | K36: =SUM(K38:K41) -> 0 | M36: =SUM(M38:M41) -> 0 | O36: =J36-K36 -> 20400000 | P36: =J36-M36 -> 20400000
D37: (KPPN.182-Jakarta VII ) | O37: =J37-K37 -> 0 | P37: =J37-M37 -> 0
D38: - | E38: Konsumsi dan Snack Siswa [25 Org x 2 keg x 1 Rom] | G38: 50 | H38: OK | I38: 53000 | J38: =G38*I38 -> 2650000 | O38: =J38-K38 -> 2650000 | P38: =J38-M38 -> 2650000
D39: - | E39: Sarana Pendukung Keagamaan [5 keg x 1 lo] | G39: 5 | H39: OK | I39: 500000 | J39: =G39*I39 -> 2500000 | O39: =J39-K39 -> 2500000 | P39: =J39-M39 -> 2500000
D40: - | E40: Dokumentasi dan Pelaporan [1 KEG x 1 LOK] | G40: 1 | H40: KEG | I40: 250000 | J40: =G40*I40 -> 250000 | O40: =J40-K40 -> 250000 | P40: =J40-M40 -> 250000
D41: - | E41: Media Pembelajaran [25 ORG x 2 KEG x 1 ROM] | G41: 50 | H41: OK | I41: 300000 | J41: =G41*I41 -> 15000000 | O41: =J41-K41 -> 15000000 | P41: =J41-M41 -> 15000000
...

Sheet SMP
G1: VOL | H1: SAT | I1: H SATUAN | J1: PAGU | K1: REALISASI | O1: SALDO
K2: SP2D | L2: % | M2: AKRURAL | N2: % | O2: SP2D | P2: AKRURAL
A3: 027.01.DQ | D3: Program Perlindungan Sosial | J3: 2097544232000 | O3: SILPA
A4: 7936 | D4: Penyelenggaraan Program Sekolah Rakyat | J4: 2088632535000
A5: 7936.SBE | D5: Pendidikan Non Gelar[Base Line] | J5: 585449649000
D6: Lokasi : KOTA JAKARTA PUSAT
A7: 7936.SBE.101 | D7: Penyelenggaraan Pendidikan Menengah Pertama Sekolah Rakyat | J7: =J8+J152+J296+J440+J584+J728+J872+J1016+J1160 -> 27555464000 | K7: =K8+K152+K296+K440+K584+K728+K872+K1016+K1160 -> 1112850000 | L7: =(K7/J7)*100 -> 4.038582 | M7: =M8+M152+M296+M440+M584+M728+M872+M1016+M1160 -> 3110242234 | N7: =(M7/J7)*100 -> 11.287207 | O7: =J7-K7 -> 26442614000 | P7: =J7-M7 -> 24445221766
A8: 128 | D8: Sekolah Rakyat Menengah Pertama 28 Pasuruan | J8: =J9+J23+J35+J48+J65+J74+J84+J89+J105+J119+J127+J135+J141 -> 3064496000 | K8: =K9+K23+K35+K48+K65+K74+K84+K89+K105+K119+K127+K135+K141 -> 193110000 | M8: =M9+M23+M35+M48+M65+M74+M84+M89+M105+M119+M127+M135+M141 -> 319604995 | O8: =J8-K8 -> 2871386000 | P8: =J8-M8 -> 2744891005
A9: A | D9: Kegiatan Belajar Mengajar | J9: =J10+J19 -> 142640000 | K9: =K10+K19 -> 0 | M9: =M10+M19 -> 14680146 | O9: =J9-K9 -> 142640000 | P9: =J9-M9 -> 127959854
A10: 521211 | D10: Belanja Bahan | J10: =SUM(J12:J18) -> 130640000 | K10: =SUM(K12:K18) -> 0 | M10: =SUM(M12:M18) -> 14380146 | O10: =J10-K10 -> 130640000 | P10: =J10-M10 -> 116259854
D11: (KPPN.182-Jakarta VII ) | O11: =J11-K11 -> 0 | P11: =J11-M11 -> 0
D12: - | E12: ATK Kelas [1 PKT x 12 BLN x 2 ROM] | G12: 24 | H12: OK | I12: 500000 | J12: =G12*I12 -> 12000000 | O12: =J12-K12 -> 12000000 | P12: =J12-M12 -> 12000000 | Q12: 14788300
D13: - | E13: Buku Pegangan Guru [1 PKT x 2 SMT x 1 LOK] | G13: 2 | H13: OK | I13: 2000000 | J13: =G13*I13 -> 4000000 | O13: =J13-K13 -> 4000000 | P13: =J13-M13 -> 4000000
D14: - | E14: Buku Penunjang Kegiatan Belajar Mengajar [5 PKT x 2 SMT x 1 LOK] | G14: 10 | H14: OK | I14: 500000 | J14: =G14*I14 -> 5000000 | O14: =J14-K14 -> 5000000 | P14: =J14-M14 -> 5000000
D15: - | E15: Penggandaan Soal [25 ORG x 4 KEG x 2 ROM] | G15: 200 | H15: OK | I15: 25000 | J15: =G15*I15 -> 5000000 | O15: =J15-K15 -> 5000000 | P15: =J15-M15 -> 5000000
D16: - | E16: Konsumsi Rapat Eksternal [40 ORG x 4 KEG x 2 HR x 1 LOK | G16: 320 | H16: OK | I16: 53000 | J16: =G16*I16 -> 16960000 | M16: 8733000 | O16: =J16-K16 -> 16960000 | P16: =J16-M16 -> 8227000 | Q16: 8490000
D17: - | E17: Snack Rapat Eksternal [40 ORG x 4 KEG x 2 HR x 1 LOK | G17: 320 | H17: OK | I17: 24000 | J17: =G17*I17 -> 7680000 | O17: =J17-K17 -> 7680000 | P17: =J17-M17 -> 7680000 | Q17: 3180000
D18: - | E18: Media Pembelajaran dan Laporan Perkembangan Siswa [25 ORG x 2 PKT x 2 ROM] | G18: 100 | H18: OK | I18: 800000 | J18: =G18*I18 -> 80000000 | M18: 5647146 | O18: =J18-K18 -> 80000000 | P18: =J18-M18 -> 74352854 | Q18: 126625500
A19: 522151 | D19: Belanja Jasa Profesi | J19: =SUM(J21:J22) -> 12000000 | K19: =SUM(K21:K22) -> 0 | M19: =SUM(M21:M22) -> 300000 | O19: =J19-K19 -> 12000000 | P19: =J19-M19 -> 11700000
D20: (KPPN.182-Jakarta VII ) | O20: =J20-K20 -> 0 | P20: =J20-M20 -> 0
D21: - | E21: Honor Instruktur [4 ORG x 2 Jam x 2 ROM] | G21: 16 | H21: OK | I21: 500000 | J21: =G21*I21 -> 8000000 | O21: =J21-K21 -> 8000000 | P21: =J21-M21 -> 8000000 | Q21: 4000000
D22: - | E22: Honor Narasumber [2 ORG x 2 Jam x 2 Keg] | G22: 8 | H22: OK | I22: 500000 | J22: =G22*I22 -> 4000000 | M22: 300000 | O22: =J22-K22 -> 4000000 | P22: =J22-M22 -> 3700000 | Q22: 3000000
A23: B | D23: Praktikum Komunitas | J23: =J24+J29+J32 -> 24400000 | K23: =K24+K29+K32 -> 0 | M23: =M24+M29+M32 -> 40000 | O23: =J23-K23 -> 24400000 | P23: =J23-M23 -> 24360000
A24: 521211 | D24: Belanja Bahan | J24: =SUM(J26:J28) -> 6400000 | K24: =SUM(K26:K28) -> 0 | M24: =SUM(M26:M28) -> 40000 | O24: =J24-K24 -> 6400000 | P24: =J24-M24 -> 6360000
D25: (KPPN.182-Jakarta VII ) | O25: =J25-K25 -> 0 | P25: =J25-M25 -> 0
D26: - | E26: Snack dan Konsumsi Siswa [25 ORG x 2 keg x 2 Rom] | G26: 100 | H26: OK | I26: 53000 | J26: =G26*I26 -> 5300000 | O26: =J26-K26 -> 5300000 | P26: =J26-M26 -> 5300000
D27: - | E27: Dokumentasi Pelaporan [1 KEG x 2 LOK] | G27: 2 | H27: OK | I27: 250000 | J27: =G27*I27 -> 500000 | O27: =J27-K27 -> 500000 | P27: =J27-M27 -> 500000
D28: - | E28: Spanduk [1 KEG x 2 LOK] | G28: 2 | H28: OK | I28: 300000 | J28: =G28*I28 -> 600000 | M28: 40000 | O28: =J28-K28 -> 600000 | P28: =J28-M28 -> 560000
A29: 521213 | D29: Belanja Honor Output Kegiatan | J29: =J31 -> 2000000 | K29: =K31 | M29: =M31 | O29: =J29-K29 -> 2000000 | P29: =J29-M29 -> 2000000
D30: (KPPN.182-Jakarta VII ) | O30: =J30-K30 -> 0 | P30: =J30-M30 -> 0
D31: - | E31: Honor Pemandu Praktikum [2 ORG x 2 KEG] | G31: 4 | H31: OK | I31: 500000 | J31: =G31*I31 -> 2000000 | O31: =J31-K31 -> 2000000 | P31: =J31-M31 -> 2000000
A32: 522141 | D32: Belanja Sewa | J32: =J34 -> 16000000 | K32: =K34 | M32: =M34 | O32: =J32-K32 -> 16000000 | P32: =J32-M32 -> 16000000
D33: (KPPN.182-Jakarta VII ) | O33: =J33-K33 -> 0 | P33: =J33-M33 -> 0
D34: - | E34: Sewa Bus [1 UNIT x 2 keg x 2 ROm] | G34: 4 | H34: OK | I34: 4000000 | J34: =G34*I34 -> 16000000 | O34: =J34-K34 -> 16000000 | P34: =J34-M34 -> 16000000
A35: C | D35: Kegiatan Krida | J35: =J36+J42+J45 -> 56050000 | K35: =K36+K42+K45 -> 0 | M35: =M36+M42+M45 -> 0 | O35: =J35-K35 -> 56050000 | P35: =J35-M35 -> 56050000
A36: 521211 | D36: Belanja Bahan | J36: =SUM(J38:J41) -> 38050000 | K36: =SUM(K38:K41) -> 0 | M36: =SUM(M38:M41) -> 0 | O36: =J36-K36 -> 38050000 | P36: =J36-M36 -> 38050000
D37: (KPPN.182-Jakarta VII ) | O37: =J37-K37 -> 0 | P37: =J37-M37 -> 0
D38: - | E38: Konsumsi dan Snack Siswa [25 Org x 2 keg x 2 Rom] | G38: 100 | H38: OK | I38: 53000 | J38: =G38*I38 -> 5300000 | O38: =J38-K38 -> 5300000 | P38: =J38-M38 -> 5300000
D39: - | E39: Sarana Pendukung Keagamaan [5 keg x 1 lo] | G39: 5 | H39: OK | I39: 500000 | J39: =G39*I39 -> 2500000 | O39: =J39-K39 -> 2500000 | P39: =J39-M39 -> 2500000
D40: - | E40: Dokumentasi dan Pelaporan [1 KEG x 1 LOK] | G40: 1 | H40: KEG | I40: 250000 | J40: =G40*I40 -> 250000 | O40: =J40-K40 -> 250000 | P40: =J40-M40 -> 250000
...

Sheet SMA
J2: PAGU | K2: REALISASI | O2: SALDO | Q2: PAGU
K3: SP2D | L3: % | M3: AKRURAL | N3: % | O3: SP2D | P3: AKRURAL
A4: 027.01.DQ | D4: Program Perlindungan Sosial | J4: 2097544232000 | Q4: 2097544232000
A5: 7936 | D5: Penyelenggaraan Program Sekolah Rakyat | J5: 2088632535000 | Q5: 2088632535000
A6: 7936.SBB | D6: Pendidikan Menengah[Penambahan alokasi dari SABA 999.08 ke 9A] | G6: 14575.0 Orang | H6: 14575.0 Orang | J6: 650993737000 | Q6: 650993737000
D7: Lokasi : KOTA JAKARTA PUSAT
A8: 7936.SBB.101 | D8: Penyelenggaraan Pendidikan Menengah Atas Sekolah Rakyat | G8: 14575.0 Orang | H8: 14575.0 Orang | J8: 650993737000 | K8: =K9+K153+K297+K441+K585+K729+K873+K1017+K1161+K1305+K1449 -> 1336068710 | L8: =(K8/J8)*100 -> 0.20523526 | M8: =M9+M153+M297+M441+M585+M729+M873+M1017+M1161+M1305+M1449 -> 775505596 | N8: =(K8/J8)*100 -> 0.20523526 | O8: =O9+O153+O297+O441+O585+O729+O873+O1017+O1161+O1305+O1449 -> 41412762290 | P8: =P9+P153+P297+P441+P585+P729+P873+P1017+P1161+P1305+P1449 -> 41116911526 | Q8: 650993737000
A9: 210 | D9: Sekolah Rakyat Menengah Atas 10 Jakarta Selatan | J9: =J10+J24+J36+J49+J66+J75+J85+J90+J106+J120+J128+J136+J142 -> 5105246000 | K9: =K10+K24+K36+K49+K66+K75+K85+K90+K106+K120+K128+K136+K142 -> 314938900 | L9: =(K9/J9)*100 -> 6.168927 | M9: =M10+M24+M36+M49+M66+M75+M85+M90+M106+M120+M128+M136+M142 -> 775505596 | N9: =(K9/J9)*100 -> 6.168927 | O9: =O10+O24+O36+O49+O66+O75+O85+O90+O106+O120+O128+O136+O142 -> 4758307100 | P9: =P10+P24+P36+P49+P66+P75+P85+P90+P106+P120+P128+P136+P142 -> 4297740404 | Q9: 5073246000 | R9: 346295364 | S9: 6,83
A10: A | D10: Kegiatan Belajar Mengajar | J10: =J11+J20 -> 247640000 | K10: =K11+K20 -> 0 | L10: =(K10/J10)*100 -> 0 | M10: =M11+M20 -> 74991832 | N10: =(K10/J10)*100 -> 0 | O10: =O11+O20 -> 247640000 | P10: =P11+P20 -> 172648168 | Q10: =Q11+Q20 -> 247640000
A11: 521211 | D11: Belanja Bahan | J11: =SUM(J13:J19) -> 227640000 | K11: =SUM(K13:K19) -> 0 | L11: =(K11/J11)*100 -> 0 | M11: =SUM(M13:M19) -> 74441832 | N11: =(K11/J11)*100 -> 0 | O11: =SUM(O13:O19) -> 227640000 | P11: =SUM(P13:P19) -> 153198168 | Q11: =SUM(Q13:Q19) -> 227640000
D12: (KPPN.182-Jakarta VII )
D13: - | E13: ATK Kelas [1 PKT x 12 BLN x 4 ROM] | G13: 48 | H13: OK | I13: 500000 | J13: =G13*I13 -> 24000000 | L13: =(K13/J13)*100 -> 0 | M13: 1574440 | N13: =(K13/J13)*100 -> 0 | O13: =J13-K13 -> 24000000 | P13: =J13-M13 -> 22425560 | Q13: 24000000 | R13: 12321800
D14: - | E14: Buku Pegangan Guru [1 PKT x 2 SMT x 1 LOK] | G14: 2 | H14: OK | I14: 2000000 | J14: =G14*I14 -> 4000000 | L14: =(K14/J14)*100 -> 0 | M14: 3037670 | N14: =(K14/J14)*100 -> 0 | O14: =J14-K14 -> 4000000 | P14: =J14-M14 -> 962330 | Q14: 4000000
D15: - | E15: Buku Penunjang Kegiatan Belajar Mengajar [5 PKT x 2 SMT x 1 LOK] | G15: 10 | H15: OK | I15: 500000 | J15: =G15*I15 -> 5000000 | L15: =(K15/J15)*100 -> 0 | M15: 16203000 | N15: =(K15/J15)*100 -> 0 | O15: =J15-K15 -> 5000000 | P15: =J15-M15 -> -11203000 | Q15: 5000000
D16: - | E16: Penggandaan Soal [25 ORG x 4 KEG x 4 ROM] | G16: 400 | H16: OK | I16: 25000 | J16: =G16*I16 -> 10000000 | L16: =(K16/J16)*100 -> 0 | M16: 487500 | N16: =(K16/J16)*100 -> 0 | O16: =J16-K16 -> 10000000 | P16: =J16-M16 -> 9512500 | Q16: 10000000
D17: - | E17: Konsumsi Rapat Eksternal [40 ORG x 4 KEG x 2 HR x 1 LOK | G17: 320 | H17: OK | I17: 53000 | J17: =G17*I17 -> 16960000 | L17: =(K17/J17)*100 -> 0 | M17: 11136600 | N17: =(K17/J17)*100 -> 0 | O17: =J17-K17 -> 16960000 | P17: =J17-M17 -> 5823400 | Q17: 16960000 | R17: 13705000
D18: - | E18: Snack Rapat Eksternal [40 ORG x 4 KEG x 2 HR x 1 LOK | G18: 320 | H18: OK | I18: 24000 | J18: =G18*I18 -> 7680000 | L18: =(K18/J18)*100 -> 0 | M18: 6143000 | N18: =(K18/J18)*100 -> 0 | O18: =J18-K18 -> 7680000 | P18: =J18-M18 -> 1537000 | Q18: 7680000 | R18: 5448000
D19: - | E19: Media Pembelajaran dan Laporan Perkembangan Siswa [25 ORG x 2 PKT x 4 ROM] | G19: 200 | H19: OK | I19: 800000 | J19: =G19*I19 -> 160000000 | L19: =(K19/J19)*100 -> 0 | M19: 35859622 | N19: =(K19/J19)*100 -> 0 | O19: =J19-K19 -> 160000000 | P19: =J19-M19 -> 124140378 | Q19: 160000000 | R19: 66856000
A20: 522151 | D20: Belanja Jasa Profesi | J20: =SUM(J22:J23) -> 20000000 | K20: =SUM(K22:K23) -> 0 | L20: =(K20/J20)*100 -> 0 | M20: =SUM(M22:M23) -> 550000 | N20: =(K20/J20)*100 -> 0 | O20: =SUM(O22:O23) -> 20000000 | P20: =SUM(P22:P23) -> 19450000 | Q20: =SUM(Q22:Q23) -> 20000000
D21: (KPPN.182-Jakarta VII )
D22: - | E22: Honor Instruktur [4 ORG x 2 Jam x 4 ROM] | G22: 32 | H22: OK | I22: 500000 | J22: =G22*I22 -> 16000000 | L22: =(K22/J22)*100 -> 0 | N22: =(K22/J22)*100 -> 0 | O22: =J22-K22 -> 16000000 | P22: =J22-M22 -> 16000000 | Q22: 16000000 | R22: 4500000
D23: - | E23: Honor Narasumber [2 ORG x 2 JAM x 2 KEG] | G23: 8 | H23: OK | I23: 500000 | J23: =G23*I23 -> 4000000 | L23: =(K23/J23)*100 -> 0 | M23: 550000 | N23: =(K23/J23)*100 -> 0 | O23: =J23-K23 -> 4000000 | P23: =J23-M23 -> 3450000 | Q23: 4000000 | R23: 1000000
A24: B | D24: Praktikum Komunitas | J24: =J25+J30+J33 -> 45700000 | K24: =K25+K30+K33 -> 0 | L24: =(K24/J24)*100 -> 0 | M24: =M25+M30+M33 -> 15107300 | N24: =(K24/J24)*100 -> 0 | O24: =O25+O30+O33 -> 45700000 | P24: =P25+P30+P33 -> 30592700 | Q24: 45700000
A25: 521211 | D25: Belanja Bahan | J25: =SUM(J27:J29) -> 11700000 | K25: =SUM(K27:K29) -> 0 | L25: =(K25/J25)*100 -> 0 | M25: =SUM(M27:M29) -> 6397300 | N25: =(K25/J25)*100 -> 0 | O25: =SUM(O27:O29) -> 11700000 | P25: =SUM(P27:P29) -> 5302700 | Q25: 11700000
D26: (KPPN.182-Jakarta VII )
D27: - | E27: Snack dan Konsumsi Siswa [25 ORG x 2 keg x 4 Rom] | G27: 200 | H27: OK | I27: 53000 | J27: =G27*I27 -> 10600000 | L27: =(K27/J27)*100 -> 0 | M27: 6297300 | N27: =(K27/J27)*100 -> 0 | O27: =J27-K27 -> 10600000 | P27: =J27-M27 -> 4302700 | Q27: 10600000
D28: - | E28: Dokumentasi Pelaporan [1 KEG x 2 LOK] | G28: 2 | H28: OK | I28: 250000 | J28: =G28*I28 -> 500000 | L28: =(K28/J28)*100 -> 0 | N28: =(K28/J28)*100 -> 0 | O28: =J28-K28 -> 500000 | P28: =J28-M28 -> 500000 | Q28: 500000
D29: - | E29: Spanduk [1 KEG x 2 LOK] | G29: 2 | H29: OK | I29: 300000 | J29: =G29*I29 -> 600000 | L29: =(K29/J29)*100 -> 0 | M29: 100000 | N29: =(K29/J29)*100 -> 0 | O29: =J29-K29 -> 600000 | P29: =J29-M29 -> 500000 | Q29: 600000 | R29: 450000
A30: 521213 | D30: Belanja Honor Output Kegiatan | J30: =J32 -> 2000000 | K30: =K32 | L30: =(K30/J30)*100 -> 0 | M30: =M32 -> 1110000 | N30: =(K30/J30)*100 -> 0 | O30: =O32 -> 2000000 | P30: =P32 -> 890000 | Q30: 2000000
D31: (KPPN.182-Jakarta VII )
D32: - | E32: Honor Pemandu Praktikum [2 ORG x 2 KEG] | G32: 4 | H32: OK | I32: 500000 | J32: =G32*I32 -> 2000000 | L32: =(K32/J32)*100 -> 0 | M32: 1110000 | N32: =(K32/J32)*100 -> 0 | O32: =J32-K32 -> 2000000 | P32: =J32-M32 -> 890000 | Q32: 2000000
A33: 522141 | D33: Belanja Sewa | J33: =J35 -> 32000000 | K33: =K35 | L33: =(K33/J33)*100 -> 0 | M33: =M35 -> 7600000 | N33: =(K33/J33)*100 -> 0 | O33: =O35 -> 32000000 | P33: =P35 -> 24400000 | Q33: 32000000
D34: (KPPN.182-Jakarta VII )
D35: - | E35: Sewa Bus [1 UNIT x 2 keg x 4 ROm] | G35: 8 | H35: OK | I35: 4000000 | J35: =G35*I35 -> 32000000 | L35: =(K35/J35)*100 -> 0 | M35: 7600000 | N35: =(K35/J35)*100 -> 0 | O35: =J35-K35 -> 32000000 | P35: =J35-M35 -> 24400000 | Q35: 32000000
A36: C | D36: Kegiatan Krida | J36: =J37+J43+J46 -> 107350000 | K36: =K37+K43+K46 -> 0 | L36: =(K36/J36)*100 -> 0 | M36: =M37+M43+M46 -> 0 | N36: =(K36/J36)*100 -> 0 | O36: =O37+O43+O46 -> 107350000 | P36: =P37+P43+P46 -> 107350000 | Q36: 107350000 | R36: 22200000
A37: 521211 | D37: Belanja Bahan | J37: =SUM(J39:J42) -> 73350000 | K37: =SUM(K39:K42) -> 0 | L37: =(K37/J37)*100 -> 0 | M37: =SUM(M39:M42) -> 0 | N37: =(K37/J37)*100 -> 0 | O37: =SUM(O39:O42) -> 73350000 | P37: =SUM(P39:P42) -> 73350000 | Q37: 73350000
D38: (KPPN.182-Jakarta VII )
D39: - | E39: Konsumsi dan Snack Siswa [25 Org x 2 keg x 4 Rom] | G39: 200 | H39: OK | I39: 53000 | J39: =G39*I39 -> 10600000 | L39: =(K39/J39)*100 -> 0 | N39: =(K39/J39)*100 -> 0 | O39: =J39-K39 -> 10600000 | P39: =J39-M39 -> 10600000 | Q39: 10600000
D40: - | E40: Sarana Pendukung Keagamaan [5 keg x 1 lo] | G40: 5 | H40: OK | I40: 500000 | J40: =G40*I40 -> 2500000 | L40: =(K40/J40)*100 -> 0 | N40: =(K40/J40)*100 -> 0 | O40: =J40-K40 -> 2500000 | P40: =J40-M40 -> 2500000 | Q40: 2500000
D41: - | E41: Dokumentasi dan Pelaporan [1 KEG x 1 LOK] | G41: 1 | H41: KEG | I41: 250000 | J41: =G41*I41 -> 250000 | L41: =(K41/J41)*100 -> 0 | N41: =(K41/J41)*100 -> 0 | O41: =J41-K41 -> 250000 | P41: =J41-M41 -> 250000 | Q41: 250000
...

Sheet LAYANAN PERKANTORAN
D1: REALISASI AKRURAL
D2: WA.7937.EBA.994.002.F.522191 | I2: JAKSEL | J2: UNESA | K2: LAMONGAN | L2: MALANG | M2: PASURUAN 3 | N2: TRENGGALEK 50 | O2: PASURUAN 48 | P2: PASURUAN 28 | Q2: PROBOLINGGO | R2: BANYUWANGI 2 | S2: BANYUWANGI 47 | T2: BANGKALAN | U2: PAMEKASAN | V2: SUMENEP | W2: PACITAN | X2: PONOROGO | Y2: TOTAL REALISASI | Z2: SILPA
C3: 7937.EBA.994 | D3: Layanan Perkantoran
C4: 002 | D4: Operasional dan Pemeliharaan Kantor | H4: =H6+H9+H12 -> 5686500000 | I4: =I6+I9+I12 -> 24385727 | J4: =J6+J9+J12 -> 0 | K4: =K6+K9+K12 -> 600000 | L4: =L6+L9+L12 -> 0 | M4: =M6+M9+M12 -> 0 | N4: =N6+N9 -> 72404051 | O4: =O6+O9+O12 -> 62626091 | P4: =P6+P9+P12 -> 0 | Q4: =Q6+Q9+Q12 -> 0 | R4: =R6+R9+R12 -> 0 | S4: =S6+S9+S12 -> 0 | T4: =T6+T9+T12 -> 0 | U4: =U6+U9+U12 -> 0 | V4: =V6+V9+V12 -> 0 | ... X4: =X6+X9+X12 -> 177967879 | Y4: =SUM(I4:X4) -> 432079926 | Z4: =H4-Y4 -> 5254420074
C5: F | D5: Operasional Perkantoran | Y5: =SUM(I5:W5) -> 0 | Z5: =H5-Y5 -> 0
C6: 521111 | D6: Belanja Keperluan Perkantoran | H6: =H7+H8 -> 2835000000 | I6: =I7+I8 -> 24385727 | J6: =J7+J8 -> 0 | K6: =K7+K8 -> 600000 | L6: =L7+L8 -> 0 | M6: =M7+M8 -> 0 | N6: =N7 -> 51804051 | O6: =O7+O8 -> 19751171 | P6: =P7+P8 -> 0 | Q6: =Q7+Q8 -> 0 | R6: =R7+R8 -> 0 | S6: =S7+S8 -> 0 | T6: =T7+T8 -> 0 | U6: =U7+U8 -> 0 | V6: =V7+V8 -> 0 | ... X6: =X7+X8 -> 140259131 | Y6: =SUM(I6:X6) -> 317058080 | Z6: =H6-Y6 -> 2517941920
D7: Keperluan Sehari-hari Perkantoran [1 pkt x 12 bln x 300] | E7: 180 | F7: PKT | G7: 15000000 | H7: =G7*E7 -> 2700000000 | I7: 24385727 | N7: 51804051 | O7: 16360936 | W7: 79208000 | X7: 140259131 | Y7: =SUM(I7:X7) -> 312017845 | Z7: =H7-Y7 -> 2387982155
D8: Biaya Retrebusi Sampah [1 pkt x 12 bln x 300 lok] | E8: 180 | F8: PKT | G8: 750000 | H8: =G8*E8 -> 135000000 | K8: 600000 | O8: 3390235 | W8: 1050000 | Y8: =SUM(I8:X8) -> 5040235 | Z8: =H8-Y8 -> 129959765
C9: 522141 | D9: Belanja Sewa | H9: =H10+H11 -> 151500000 | I9: =I10+I11 -> 0 | J9: =J10+J11 -> 0 | K9: =K10+K11 -> 0 | L9: =L10+L11 -> 0 | M9: =M10+M11 -> 0 | N9: 20600000 | O9: =O10+O11 -> 0 | P9: =P10+P11 -> 0 | Q9: =Q10+Q11 -> 0 | R9: =R10+R11 -> 0 | S9: =S10+S11 -> 0 | T9: =T10+T11 -> 0 | U9: =U10+U11 -> 0 | V9: =V10+V11 -> 0 | ... X9: =X10+X11 -> 22000000 | Y9: =SUM(I9:X9) -> 42600000 | Z9: =H9-Y9 -> 108900000
D10: Sewa Kendaraan [1 pkt x 12 bln x 300 lok] | E10: 135 | F10: PKT | G10: 900000 | H10: =G10*E10 -> 121500000 | Y10: =SUM(I10:X10) -> 0 | Z10: =H10-Y10 -> 121500000
D11: Sewa Mesin Fotocopy [1 pkt x 12 bln x 300 lok] | E11: 15 | F11: PKT | G11: 2000000 | H11: =G11*E11 -> 30000000 | X11: 22000000 | Y11: =SUM(I11:X11) -> 22000000 | Z11: =H11-Y11 -> 8000000
C12: 522191 | D12: Belanja jasa Lainnya | H12: =H14 -> 2700000000 | I12: =I14 | J12: =J14 | K12: =K14 | L12: =L14 | M12: =M14 | O12: 42874920 | P12: =P14 | Q12: =Q14 | R12: =R14 | S12: =S14 | T12: =T14 | U12: =U14 | V12: =V14 | W12: =W14 -> 13838178 | X12: =X14 -> 15708748 | Y12: =SUM(I12:X12) -> 72421846 | Z12: =H12-Y12 -> 2627578154
D13: (KPPN, 182-Jakarta VII) | Y13: =SUM(I13:X13) -> 0 | Z13: =H13-Y13 -> 0
D14: Pembayaran Listrik dan PDAM ( 1 pkt x 12 bln x 15 lok) | E14: 180 | F14: PKT | G14: 15000000 | H14: =E14*G14 -> 2700000000 | O14: =7536510+9610060+8497760+17230590 -> 42874920 | W14: 13838178 | X14: 15708748 | Y14: =SUM(I14:X14) -> 72421846 | Z14: =H14-Y14 -> 2627578154
O17: jasa pos
O18: 76500
O19: servis /perbaikan
O20: 2800000

Sheet berdasarAnggaran
B3: KODE | C3: PROGRAM/KEG/KOM/SUBKOMP/AKUN | D3: PAGU | E3: REALISASI | I3: SALDO
E4: SP2D | G4: AKRURAL | I4: SP2D | J4: AKRURAL
B5: 027.01.DQ | C5: Program Perlindungan Sosial
B6: 7936 | C6: Penyelenggaraan Program Sekolah Rakyat
B7: 7936.SBC | C7: Pendidikan Dasar[Penambahan alokasi dari SABA 999.08 ke 9A]
B8: 302 | C8: Sekolah Rakyat Terintegrasi 2 Banyuwangi | D8: =SD!J8 -> 2060121000 | E8: =SD!K8 -> 44809500 | F8: =SD!L8 | G8: =SD!M8 -> 172139900 | H8: =SD!N8 | I8: =SD!O8 -> 2015311500 | J8: =SD!P8 -> 1887981100 | K8: =SD!Q8
B9: =SD!B152 -> 407 | C9: =SD!D152 -> Sekolah Rakyat 1C Terintegrasi 07 Kabupaten Banyuwangi | D9: =SD!J152 -> 3064496000 | E9: =SD!K152 -> 53112000 | F9: =SD!L152 | G9: =SD!M152 -> 137854831 | H9: =SD!N152 | I9: =SD!O152 -> 3011384000 | J9: =SD!P152 -> 2926641169 | K9: =SD!Q152
B10: =SD!B296 -> 408 | C10: =SD!D296 -> Sekolah Rakyat 1C Terintegrasi 08 Kabupaten Pasuruan | D10: =SD!J296 -> 3064496000 | E10: =SD!K296 -> 170789000 | F10: =SD!L296 | G10: =SD!M296 -> 295770418 | H10: =SD!N296 | I10: =SD!O296 -> 2893707000 | J10: =SD!P296 -> 2768725582 | K10: =SD!Q296
B11: =SD!B440 -> 409 | C11: =SD!D440 -> Sekolah Rakyat 1C Terintegrasi 09 Kabupaten Malang | D11: =SD!J440 -> 2060121000 | E11: =SD!K440 -> 39475500 | F11: =SD!L440 | G11: =SD!M440 -> 75503736 | H11: =SD!N440 | I11: =SD!O440 -> 2020645500 | J11: =SD!P440 -> 1984617264 | K11: =SD!Q440
B12: =SD!B584 -> 425 | C12: =SD!D584 -> Sekolah Rakyat 1C Terintegrasi 25 Kabupaten Sumenep | D12: =SD!J584 -> 3064496000 | E12: =SD!K584 -> 40651000 | F12: =SD!L584 | G12: =SD!M584 -> 56500261 | H12: =SD!N584 | I12: =SD!O584 -> 3023845000 | J12: =SD!P584 -> 3007995739 | K12: =SD!Q584
B13: =SD!B728 -> 426 | C13: =SD!D728 -> Sekolah Rakyat 1C Terintegrasi 26 Kabupaten Trenggalek | D13: =SD!J728 -> 3064496000 | E13: =SD!K728 -> 147431000 | F13: =SD!L728 | G13: =SD!M728 -> 281790116 | H13: =SD!N728 | I13: =SD!O728 -> 2917065000 | J13: =SD!P728 -> 2782705884 | K13: =SD!Q728
B14: =SD!B872 -> 427 | C14: =SD!D872 -> Sekolah Rakyat 1C Terintegrasi 27 Kab Bangkalan | D14: =SD!J872 -> 3064496000 | E14: =SD!K872 -> 86340000 | F14: =SD!L872 | G14: =SD!M872 -> 200051918 | H14: =SD!N872 | I14: =SD!O872 -> 2978156000 | J14: =SD!P872 -> 2864444082 | K14: =SD!Q872
B15: =SD!D1016 | C15: =SD!E1016 -> Sekolah Rakyat Terintegrasi 5 Ponorogo | D15: =SD!J1016 -> 2060121000 | E15: =SD!K1016 -> 120244000 | F15: =SD!L1016 | G15: =SD!M1016 -> 135116311 | H15: =SD!N1016 | I15: =SD!O1016 -> 1939877000 | J15: =SD!P1016 -> 1925004689 | K15: =SD!Q1016
D16: =SUM(D8:D15) -> 21502843000
B17: =SMP!A5 -> 7936.SBE | C17: =SMP!D7 -> Penyelenggaraan Pendidikan Menengah Pertama Sekolah Rakyat
B18: =SMP!A8 -> 128 | C18: =SMP!D8 -> Sekolah Rakyat Menengah Pertama 28 Pasuruan | D18: =SMP!J8 -> 3064496000 | E18: =SMP!K8 -> 193110000 | F18: =SMP!L8 | G18: =SMP!M8 -> 319604995 | H18: =SMP!N8 | I18: =SMP!O8 -> 2871386000 | J18: =SMP!P8 -> 2744891005 | K18: =SMP!Q8
B19: =SMP!A152 -> 129 | C19: =SMP!D152 -> Sekolah Rakyat Menengah Pertama 29 Pamekasan | D19: =SMP!J152 -> 3064496000 | E19: =SMP!K152 -> 122890200 | F19: =SMP!L152 | G19: =SMP!M152 -> 261884590 | H19: =SMP!N152 | I19: =SMP!O152 -> 2941605800 | J19: =SMP!P152 -> 2802611410 | K19: =SMP!Q152
B20: =SMP!A296 -> 302 | C20: =SMP!D296 -> Sekolah Rakyat Terintegrasi 2 Banyuwangi | D20: =SMP!J296 -> 3064496000 | E20: =SMP!K296 -> 83250000 | F20: =SMP!L296 | G20: =SMP!M296 -> 198653500 | H20: =SMP!N296 | I20: =SMP!O296 -> 2981246000 | J20: =SMP!P296 -> 2865842500 | K20: =SMP!Q296
B21: =SMP!A440 -> 303 | C21: =SMP!D440 -> Sekolah Rakyat Terintegrasi 3 Pasuruan | D21: =SMP!J440 -> 4068871000 | E21: =SMP!K440 -> 209098300 | F21: =SMP!L440 | G21: =SMP!M440 -> 291470438 | H21: =SMP!N440 | I21: =SMP!O440 -> 3859772700 | J21: =SMP!P440 -> 3777400562 | K21: =SMP!Q440
B22: =SMP!A584 -> 426 | C22: =SMP!D584 -> Sekolah Rakyat 1C Terintegrasi 26 Kabupaten Trenggalek | D22: =SMP!J584 -> 2035121000 | E22: =SMP!K584 -> 33612000 | F22: =SMP!L584 | G22: =SMP!M584 -> 477651045 | H22: =SMP!N584 | I22: =SMP!O584 -> 2001509000 | J22: =SMP!P584 -> 1557469955 | K22: =SMP!Q584
B23: =SMP!A728 -> 427 | C23: =SMP!D728 -> Sekolah Rakyat 1C Terintegrasi 27 Kabupaten Bangkalan | D23: =SMP!J728 -> 3064496000 | E23: =SMP!K728 -> 73800000 | F23: =SMP!L728 | G23: =SMP!M728 -> 960940010 | H23: =SMP!N728 | I23: =SMP!O728 -> 2990696000 | J23: =SMP!P728 -> 2103555990 | K23: =SMP!Q728
B24: =SMP!C872 | C24: =SMP!E872 -> Sekolah Rakyat Terintegrasi 5 Ponorogo | D24: =SMP!J872 -> 3064496000 | E24: =SMP!K872 -> 100440000 | F24: =SMP!L872 | G24: =SMP!M872 -> 219022054 | H24: =SMP!N872 | I24: =SMP!O872 -> 2964056000 | J24: =SMP!P872 -> 2845473946 | K24: =SMP!Q872
B25: =SMP!C1016 -> 307 | C25: =SMP!E1016 -> Sekolah Rakyat Terintegrasi 7 Probolinggo | D25: =SMP!J1016 -> 3064496000 | E25: =SMP!K1016 -> 54390000 | F25: =SMP!L1016 | G25: =SMP!M1016 -> 198342323 | H25: =SMP!N1016 | I25: =SMP!O1016 -> 3010106000 | J25: =SMP!P1016 -> 2866153677 | K25: =SMP!Q1016
B26: =SMP!C1160 -> 425 | C26: =SMP!E1160 -> Sekolah Rakyat 1C Terintegrasi 25 Kabupaten Sumenep | D26: =SMP!J1160 -> 3064496000 | E26: =SMP!K1160 -> 242259500 | F26: =SMP!L1160 | G26: =SMP!M1160 -> 182673279 | H26: =SMP!N1160 | I26: =SMP!O1160 -> 2822236500 | J26: =SMP!P1160 -> 2881822721 | K26: =SMP!Q1160
D27: =SUM(D18:D26) -> 27555464000
B28: =SMA!A6 -> 7936.SBB | C28: =SMA!D6 -> Pendidikan Menengah[Penambahan alokasi dari SABA 999.08 ke 9A]
B29: =SMA!A9 -> 210 | C29: =SMA!D9 -> Sekolah Rakyat Menengah Atas 10 Jakarta Selatan | D29: =SMA!J9 -> 5105246000 | E29: =SMA!K9 -> 314938900 | F29: =SMA!L9 -> 6.168927 | G29: =SMA!M9 -> 775505596 | H29: =SMA!N9 -> 6.168927 | I29: =SMA!O9 -> 4758307100 | J29: =SMA!P9 -> 4297740404 | K29: =SMA!Q9 -> 5073246000
B30: =SMA!A153 -> 221 | C30: =SMA!D153 -> Sekolah Rakyat Menengah Atas 21 Surabaya | D30: =SMA!J153 -> 5073246000 | E30: =SMA!K153 -> 190117500 | F30: =SMA!L153 -> 3.7474528 | G30: =SMA!M153 | H30: =SMA!N153 -> 3.7474528 | I30: =SMA!O153 -> 4883128500 | J30: =SMA!P153 -> 5073246000 | K30: =SMA!Q153 -> 5073246000
B31: =SMA!A297 -> 225 | C31: =SMA!D297 -> Sekolah Rakyat Menengah Atas 25 Lamongan | D31: =SMA!J297 -> 4068871000 | E31: =SMA!K297 -> 221025500 | F31: =SMA!L297 -> 5.4321088 | G31: =SMA!M297 | H31: =SMA!N297 | I31: =SMA!O297 -> 3847845500 | J31: =SMA!P297 -> 4068871000 | K31: =SMA!Q297 -> 4068871000
B32: =SMA!A441 -> 302 | C32: =SMA!D441 -> Sekolah Rakyat Terintegrasi 2 Banyuwangi | D32: =SMA!J441 -> 3064496000 | E32: =SMA!K441 -> 150042000 | F32: =SMA!L441 -> 4.8961395 | G32: =SMA!M441 | H32: =SMA!N441 | I32: =SMA!O441 -> 2914454000 | J32: =SMA!P441 -> 3064496000 | K32: =SMA!Q441 -> 3064496000
B33: =SMA!A585 -> 303 | C33: =SMA!D585 -> Sekolah Rakyat Terintegrasi 3 Pasuruan | D33: =SMA!J585 -> 4068871000 | E33: =SMA!K585 -> 198367500 | F33: =SMA!L585 | G33: =SMA!M585 | H33: =SMA!N585 | I33: =SMA!O585 -> 3870503500 | J33: =SMA!P585 -> 4068871000 | K33: =SMA!Q585 -> 4068871000
B34: =SMA!A729 -> 305 | C34: =SMA!D729 -> Sekolah Rakyat Terintegrasi 5 Ponorogo | D34: =SMA!J729 -> 3064496000 | E34: =SMA!K729 -> 110895000 | F34: =SMA!L729 | G34: =SMA!M729 | H34: =SMA!N729 | I34: =SMA!O729 -> 2953601000 | J34: =SMA!P729 -> 2785651862 | K34: =SMA!Q729 -> 3064496000
B35: =SMA!A873 -> 307 | C35: =SMA!D873 -> Sekolah Rakyat Terintegrasi 7 Probolinggo | D35: =SMA!J873 -> 3064496000 | E35: =SMA!K873 -> 0 | F35: =SMA!L873 | G35: =SMA!M873 | H35: =SMA!N873 | I35: =SMA!O873 -> 3064496000 | J35: =SMA!P873 -> 2944898884 | K35: =SMA!Q873 -> 3064496000
B36: =SMA!A1017 -> 407 | C36: =SMA!D1017 -> Sekolah Rakyat 1C Terintegrasi 07 Kabupaten Banyuwangi | D36: =SMA!J1017 -> 3064496000 | E36: =SMA!K1017 -> 0 | F36: =SMA!L1017 | G36: =SMA!M1017 | H36: =SMA!N1017 | I36: =SMA!O1017 -> 3064496000 | J36: =SMA!P1017 -> 3064496000 | K36: =SMA!Q1017 -> 3064496000
B37: =SMA!A1161 -> 408 | C37: =SMA!D1161 -> Sekolah Rakyat 1C Terintegrasi 48 Kabupaten Pasuruan | D37: =SMA!J1161 -> 3064496000 | E37: =SMA!K1161 -> 0 | F37: =SMA!L1161 | G37: =SMA!M1161 | H37: =SMA!N1161 | I37: =SMA!O1161 -> 3064496000 | J37: =SMA!P1161 -> 2606523376 | K37: =SMA!Q1161 -> 3064496000
B38: =SMA!A1305 -> 409 | C38: =SMA!D1305 -> Sekolah Rakyat 1C Terintegrasi 09 Kabupaten Malang | D38: =SMA!J1305 -> 4068871000 | E38: =SMA!K1305 -> 0 | F38: =SMA!L1305 | G38: =SMA!M1305 | H38: =SMA!N1305 | I38: =SMA!O1305 -> 4068871000 | J38: =SMA!P1305 -> 4068871000 | K38: =SMA!Q1305 -> 4068871000
B39: =SMA!A1449 -> 464 | C39: =SMA!D1449 -> Sekolah Rakyat 1C Terintegrasi 64 Kabupaten Pacitan | D39: =SMA!J1449 -> 5073246000 | E39: =SMA!K1449 -> 150682310 | F39: =SMA!L1449 | G39: =SMA!M1449 | H39: =SMA!N1449 | I39: =SMA!O1449 -> 4922563690 | J39: =SMA!P1449 -> 5073246000 | K39: =SMA!Q1449 -> 5073246000
D40: =SUM(D29:D39) -> 42780831000
